Workbook

Sheet STOCK
A1: Material | B1: MaterialDescription | C1: MODEL | D1: STOCK | F1: USED SPARES | H1: PRICE | I1: RAMADAN PROMO | J1: ISSEGODOWN | L1: DEC (MAR) | M1: JAN (APR) | N1: SHRM | O1: HOME
A2: 40010563 | B2: MAKITA AIR FILTER FOR EA3201S 423414-0 | C2: 423414-0 | D2: 4 | F2: - | H2: 18 | N2: MA236 | Q2: ART | R2: PART | S2: QTY | T2: STCK | U2: PRICE | V2: TOTAL | W2: SR | X2: HM
A3: 40010569 | B3: MAKITA BASE FOR MT580 168370-4 | C3: 168370-4 | D3: 1 | F3: - | H3: 135 | O3: 65 | Q3: =VLOOKUP(R3,'[1]MAKITA MASTERSHEET'!$E:$G,3,0) -> #N/A | S3: 1 | T3: =VLOOKUP(Q3,A:D,4,0) -> #N/A | U3: =VLOOKUP(Q3,A:H,6,0) -> #N/A | V3: =U3*S2 -> #N/A | W3: =VLOOKUP(Q3,'[2]So R'!$B:$D,3,0) -> #N/A | X3: =VLOOKUP(Q3,A:O,11,0) -> #N/A
A4: 40010559 | B4: MAKITA GEAR FOR LS1018L JM23200020 | C4: JM23200020 | D4: 4 | F4: - | H4: 251 | N4: CI02 | Q4: =VLOOKUP(R4,'[1]MAKITA MASTERSHEET'!$E:$G,3,0) -> #N/A | S4: 1 | T4: =VLOOKUP(Q4,A:D,4,0) -> #N/A | U4: =VLOOKUP(Q4,A:H,6,0) -> #N/A | V4: =U4*S3 -> #N/A | W4: =VLOOKUP(Q4,'[2]So R'!$B:$D,3,0) -> #N/A | X4: =VLOOKUP(Q4,A:O,11,0) -> #N/A
A5: 40010574 | B5: MAKITA HEX. NUT M4 FOR 5900B 931102-0 | C5: 931102-0 | D5: 9 | F5: - | H5: 6 | N5: MA279 | Q5: =VLOOKUP(R5,'[1]MAKITA MASTERSHEET'!$E:$G,3,0) -> #N/A | S5: 1 | T5: =VLOOKUP(Q5,A:D,4,0) -> #N/A | U5: =VLOOKUP(Q5,A:H,6,0) -> #N/A | V5: =U5*S4 -> #N/A | W5: =VLOOKUP(Q5,'[2]So R'!$B:$D,3,0) -> #N/A | X5: =VLOOKUP(Q5,A:O,11,0) -> #N/A
A6: 40010555 | B6: MAKITA HOLDER FOR 4304 316608-3 | C6: 316608-3 | D6: 1 | F6: - | H6: 154 | N6: MA70 | Q6: =VLOOKUP(R6,'[1]MAKITA MASTERSHEET'!$E:$G,3,0) -> #N/A | S6: 1 | T6: =VLOOKUP(Q6,A:D,4,0) -> #N/A | U6: =VLOOKUP(Q6,A:H,6,0) -> #N/A | V6: =U6*S5 -> #N/A | W6: =VLOOKUP(Q6,'[2]So R'!$B:$D,3,0) -> #N/A | X6: =VLOOKUP(Q6,A:O,11,0) -> #N/A
A7: 40010560 | B7: MAKITA KNOB LOW COVER JM27100077 | C7: JM27100077 | D7: 2 | F7: - | H7: 52 | N7: CAA11 | Q7: =VLOOKUP(R7,'[1]MAKITA MASTERSHEET'!$E:$G,3,0) -> #N/A | S7: 1 | T7: =VLOOKUP(Q7,A:D,4,0) -> #N/A | U7: =VLOOKUP(Q7,A:H,6,0) -> #N/A | V7: =U7*S6 -> #N/A | W7: =VLOOKUP(Q11,'[2]So R'!$B:$D,3,0) -> #N/A | X7: =VLOOKUP(Q11,A:O,11,0) -> #N/A
A8: 40010573 | B8: MAKITA PUSH BUTTON FOR 9045B 411625-9 | C8: 411625-9 | D8: 14 | F8: - | H8: 12 | N8: MA279 | Q8: =VLOOKUP(R8,'[1]MAKITA MASTERSHEET'!$E:$G,3,0) -> #N/A | S8: 1 | T8: =VLOOKUP(Q8,A:D,4,0) -> #N/A | U8: =VLOOKUP(Q8,A:H,6,0) -> #N/A | V8: =U8*S7 -> #N/A | W8: =VLOOKUP(Q7,'[2]So R'!$B:$D,3,0) -> #N/A | X8: =VLOOKUP(Q7,A:O,11,0) -> #N/A
A9: 40010554 | B9: MAKITA ROD FOR 4304 165089-6 | C9: 165089-6 | F9: - | H9: 594 | N9: MA70 | Q9: =VLOOKUP(R9,'[1]MAKITA MASTERSHEET'!$E:$G,3,0) -> #N/A | S9: 1 | T9: =VLOOKUP(Q9,A:D,4,0) -> #N/A | U9: =VLOOKUP(Q9,A:H,6,0) -> #N/A | V9: =U9*S8 -> #N/A | W9: =VLOOKUP(Q8,'[2]So R'!$B:$D,3,0) -> #N/A | X9: =VLOOKUP(Q8,A:O,11,0) -> #N/A
A10: 40010557 | B10: MAKITA SLIDE PLATE FOR 4304 344137-6 | C10: 344137-6 | D10: 1 | F10: - | H10: 24 | N10: MA70 | Q10: =VLOOKUP(R10,'[1]MAKITA MASTERSHEET'!$E:$G,3,0) -> #N/A | S10: 1 | T10: =VLOOKUP(Q10,A:D,4,0) -> #N/A | U10: =VLOOKUP(Q10,A:H,6,0) -> #N/A | V10: =U10*S9 -> #N/A | W10: =VLOOKUP(Q9,'[2]So R'!$B:$D,3,0) -> #N/A | X10: =VLOOKUP(Q9,A:O,11,0) -> #N/A
A11: 40010556 | B11: MAKITA SLIDER FOR 4304 310028-3 | C11: 310028-3 | D11: 1 | F11: - | H11: 169 | N11: MA70 | Q11: =VLOOKUP(R11,'[1]MAKITA MASTERSHEET'!$E:$G,3,0) -> #N/A | S11: 1 | T11: =VLOOKUP(Q11,A:D,4,0) -> #N/A | U11: =VLOOKUP(Q11,A:H,6,0) -> #N/A | V11: =U11*S22 -> #N/A | W11: =VLOOKUP(Q10,'[2]So R'!$B:$D,3,0) -> #N/A | X11: =VLOOKUP(Q10,A:O,11,0) -> #N/A
A12: 40010562 | B12: MAKITA SPINDLE FOR N5900B 323955-5 | C12: 323955-5 | D12: 2 | F12: - | H12: 58 | N12: MA279 | Q12: =VLOOKUP(R12,'[1]MAKITA MASTERSHEET'!$E:$G,3,0) -> #N/A | S12: 1 | T12: =VLOOKUP(Q12,A:D,4,0) -> #N/A | U12: =VLOOKUP(Q12,A:H,6,0) -> #N/A | V12: =U12*S16 -> #N/A | W12: =VLOOKUP(Q16,'[2]So R'!$B:$D,3,0) -> #N/A | X12: =VLOOKUP(Q16,A:O,11,0) -> #N/A
A13: 40010571 | B13: MAKITA STATOR (AL) FOR GB801 AL00000238 | C13: AL00000238 | D13: 2 | F13: - | H13: 936 | O13: 81 | Q13: =VLOOKUP(R13,'[1]MAKITA MASTERSHEET'!$E:$G,3,0) -> #N/A | S13: 1 | T13: =VLOOKUP(Q13,A:D,4,0) -> #N/A | U13: =VLOOKUP(Q13,A:H,6,0) -> #N/A | V13: =U13*S13 -> #N/A | W13: =VLOOKUP(Q17,'[2]So R'!$B:$D,3,0) -> #N/A | X13: =VLOOKUP(Q17,A:O,11,0) -> #N/A
A14: 40010566 | B14: MAKITA TOOL HOLDER FOR HR3200C 324840-5 | C14: 324840-5 | D14: 5 | F14: - | H14: 383 | N14: MA279 | Q14: =VLOOKUP(R14,'[1]MAKITA MASTERSHEET'!$E:$G,3,0) -> #N/A | S14: 1 | T14: =VLOOKUP(Q14,A:D,4,0) -> #N/A | U14: =VLOOKUP(Q14,A:H,6,0) -> #N/A | V14: =U15*S18 -> #N/A | W14: =VLOOKUP(Q18,'[2]So R'!$B:$D,3,0) -> #N/A | X14: =VLOOKUP(Q18,A:O,11,0) -> #N/A
A15: 40007265 | B15: BEVEL GEAR / JM27000167 (MLT100) | C15: JM27000167 | D15: 1 | F15: - | H15: 1 | N15: MA179 | Q15: =VLOOKUP(R15,'[1]MAKITA MASTERSHEET'!$E:$G,3,0) -> #N/A | S15: 1 | T15: =VLOOKUP(Q15,A:D,4,0) -> #N/A | U15: =VLOOKUP(Q15,A:H,6,0) -> #N/A | V15: =U15*S15 -> #N/A | W15: =VLOOKUP(Q15,'[2]So R'!$B:$D,3,0) -> #N/A | X15: =VLOOKUP(Q15,A:O,12,0) -> #N/A
A16: 40007367 | B16: CORK RUBBER PLATE 9924DB 423035-8 | C16: 423035-8 | D16: 6 | F16: - | H16: 27 | N16: i7 | O16: AB20 | Q16: =VLOOKUP(R16,'[1]MAKITA MASTERSHEET'!$E:$G,3,0) -> #N/A | S16: 1 | T16: =VLOOKUP(Q16,A:D,4,0) -> #N/A | U16: =VLOOKUP(Q16,A:H,6,0) -> #N/A | V16: =U16*S16 -> #N/A | W16: =VLOOKUP(Q16,'[2]So R'!$B:$D,3,0) -> #N/A | X16: =VLOOKUP(Q16,A:O,12,0) -> #N/A
A17: 40005644 | B17: MAKITA ARMATURE ASS'Y 240V 510173-6 MT9 | C17: 510173-6 | D17: 18 | F17: - | H17: 225 | N17: B1 | O17: 2 | Q17: =VLOOKUP(R17,'[1]MAKITA MASTERSHEET'!$E:$G,3,0) -> #N/A | S17: 1 | T17: =VLOOKUP(Q17,A:D,4,0) -> #N/A | U17: =VLOOKUP(Q17,A:H,6,0) -> #N/A | V17: =U17*S17 -> #N/A | W17: =VLOOKUP(Q17,'[2]So R'!$B:$D,3,0) -> #N/A | X17: =VLOOKUP(Q17,A:O,12,0) -> #N/A
A18: 40005642 | B18: MAKITA ARMATURE ASS'Y 240V 515844-0 RT0 | C18: 515844-0 | D18: 3 | F18: - | H18: 536 | N18: 36 | O18: 32 | Q18: =VLOOKUP(R18,'[1]MAKITA MASTERSHEET'!$E:$G,3,0) -> #N/A | S18: 1 | T18: =VLOOKUP(Q18,A:D,4,0) -> #N/A | U18: =VLOOKUP(Q18,A:H,6,0) -> #N/A | V18: =U18*S18 -> #N/A | W18: =VLOOKUP(Q18,'[2]So R'!$B:$D,3,0) -> #N/A | X18: =VLOOKUP(Q18,A:O,12,0) -> #N/A
A19: 40005581 | B19: MAKITA BEVEL GEAR 227520-1 GA5010 | C19: 227520-1 | D19: 10 | F19: - | H19: 85 | N19: ZQ06 | Q19: =VLOOKUP(R19,'[1]MAKITA MASTERSHEET'!$E:$G,3,0) -> #N/A | S19: 1 | T19: =VLOOKUP(Q19,A:D,4,0) -> #N/A | U19: =VLOOKUP(Q19,A:H,6,0) -> #N/A | V19: =U19*S19 -> #N/A | W19: =VLOOKUP(Q19,'[2]So R'!$B:$D,3,0) -> #N/A | X19: =VLOOKUP(Q19,A:O,12,0) -> #N/A
A20: 40006710 | B20: MAKITA BRUSH HOLDER COMPLETE 638498-7 B | C20: 638498-7 | D20: 9 | F20: - | H20: 20 | O20: AC32 | Q20: =VLOOKUP(R20,'[1]MAKITA MASTERSHEET'!$E:$G,3,0) -> #N/A | S20: 1 | T20: =VLOOKUP(Q20,A:D,4,0) -> #N/A | U20: =VLOOKUP(Q20,A:H,6,0) -> #N/A | V20: =U20*S20 -> #N/A | W20: =VLOOKUP(Q20,'[2]So R'!$B:$D,3,0) -> #N/A | X20: =VLOOKUP(Q20,A:O,12,0) -> #N/A
A21: 10018807 | B21: MAKITA BURRS N-FE CUT SC 10MM B-52766 | C21: B-52766 | D21: 1 | F21: - | H21: 215 | Q21: =VLOOKUP(R21,'[1]MAKITA MASTERSHEET'!$E:$G,3,0) -> #N/A | S21: 1 | T21: =VLOOKUP(Q21,A:D,4,0) -> #N/A | U21: =VLOOKUP(Q21,A:H,6,0) -> #N/A | V21: =U21*S21 -> #N/A | W21: =VLOOKUP(Q21,'[2]So R'!$B:$D,3,0) -> #N/A | X21: =VLOOKUP(Q21,A:O,12,0) -> #N/A
A22: 10018810 | B22: MAKITA BURRS N-FE CUT SF 10MM B-52794 | C22: B-52794 | D22: 3 | F22: - | H22: 215 | Q22: =VLOOKUP(R22,'[1]MAKITA MASTERSHEET'!$E:$G,3,0) -> #N/A | S22: 1 | T22: =VLOOKUP(Q22,A:D,4,0) -> #N/A | U22: =VLOOKUP(Q22,A:H,6,0) -> #N/A | V22: =U22*S22 -> #N/A | W22: =VLOOKUP(Q22,'[2]So R'!$B:$D,3,0) -> #N/A | X22: =VLOOKUP(Q22,A:O,12,0) -> #N/A
A23: 10018813 | B23: MAKITA BURRS N-FE CUT SL 10MM B-52825 | C23: B-52825 | D23: 3 | F23: - | H23: 215 | Q23: =VLOOKUP(R23,'[1]MAKITA MASTERSHEET'!$E:$G,3,0) -> #N/A | S23: 1 | T23: =VLOOKUP(Q23,A:D,4,0) -> #N/A | U23: =VLOOKUP(Q23,A:H,6,0) -> #N/A | V23: =U23*S23 -> #N/A | W23: =VLOOKUP(Q23,'[2]So R'!$B:$D,3,0) -> #N/A | X23: =VLOOKUP(Q23,A:O,12,0) -> #N/A
A24: 10018809 | B24: MAKITA BURRS SS DIA CUT SF 10MM B-52788 | C24: B-52788 | D24: 1 | F24: - | H24: 215 | Q24: =VLOOKUP(R24,'[1]MAKITA MASTERSHEET'!$E:$G,3,0) -> #N/A | S24: 1 | T24: =VLOOKUP(Q24,A:D,4,0) -> #N/A | U24: =VLOOKUP(Q24,A:H,6,0) -> #N/A | V24: =U24*S24 -> #N/A | W24: =VLOOKUP(Q24,'[2]So R'!$B:$D,3,0) -> #N/A | X24: =VLOOKUP(Q24,A:O,12,0) -> #N/A
A25: 10018812 | B25: MAKITA BURRS SS DIA CUT SL 10MM B-52819 | C25: B-52819 | D25: 1 | F25: - | H25: 215 | Q25: =VLOOKUP(R25,'[1]MAKITA MASTERSHEET'!$E:$G,3,0) -> #N/A | S25: 1 | T25: =VLOOKUP(Q25,A:D,4,0) -> #N/A | U25: =VLOOKUP(Q25,A:H,6,0) -> #N/A | V25: =U25*S25 -> #N/A | W25: =VLOOKUP(Q25,'[2]So R'!$B:$D,3,0) -> #N/A | X25: =VLOOKUP(Q25,A:O,12,0) -> #N/A
A26: 10018805 | B26: MAKITA BURRS SS STD CUT SC 10MM B-52744 | C26: B-52744 | D26: 3 | F26: - | H26: 215 | Q26: =VLOOKUP(R26,'[1]MAKITA MASTERSHEET'!$E:$G,3,0) -> #N/A | S26: 1 | T26: =VLOOKUP(Q26,A:D,4,0) -> #N/A | U26: =VLOOKUP(Q26,A:H,6,0) -> #N/A | V26: =U26*S26 -> #N/A | W26: =VLOOKUP(Q26,'[2]So R'!$B:$D,3,0) -> #N/A | X26: =VLOOKUP(Q26,A:O,12,0) -> #N/A
A27: 10018808 | B27: MAKITA BURRS SS STD CUT SF 10MM B-52772 | C27: B-52772 | D27: 3 | F27: - | H27: 215 | Q27: =VLOOKUP(R27,'[1]MAKITA MASTERSHEET'!$E:$G,3,0) -> #N/A | S27: 1 | T27: =VLOOKUP(Q27,A:D,4,0) -> #N/A | U27: =VLOOKUP(Q27,A:H,6,0) -> #N/A | V27: =SUM(V15:V26) -> #N/A | W27: =VLOOKUP(Q27,'[2]So R'!$B:$D,3,0) -> #N/A | X27: =VLOOKUP(Q27,A:O,12,0) -> #N/A
A28: 10018811 | B28: MAKITA BURRS SS STD CUT SL 10MM B-52803 | C28: B-52803 | D28: 2 | F28: - | H28: 215 | Q28: =VLOOKUP(R28,'[1]MAKITA MASTERSHEET'!$E:$G,3,0) -> #N/A | S28: 1 | T28: =VLOOKUP(Q28,A:D,4,0) -> #N/A | U28: =VLOOKUP(Q28,A:H,6,0) -> #N/A
A29: 10018814 | B29: MAKITA BURRS SS STD CUT SM 10MM B-52831 | C29: B-52831 | D29: 1 | F29: - | H29: 215 | Q29: =VLOOKUP(R29,'[1]MAKITA MASTERSHEET'!$E:$G,3,0) -> #N/A | S29: 1 | T29: =VLOOKUP(Q29,A:D,4,0) -> #N/A
A30: 40005945 | B30: MAKITA CHANGE LEVER 162244-1 | C30: 162244-1 | D30: 23 | F30: - | H30: 14 | N30: ZD02 | Q30: =VLOOKUP(R30,'[1]MAKITA MASTERSHEET'!$E:$G,3,0) -> #N/A | S30: 1
A31: 40007956 | B31: MAKITA CHARGER TP00000111 | C31: TP00000111 | D31: 4 | F31: - | H31: 332 | N31: 82 | O31: A18(BOX) | Q31: =VLOOKUP(R31,'[1]MAKITA MASTERSHEET'!$E:$G,3,0) -> #N/A | S31: 1
A32: 40006181 | B32: MAKITA CONNECTING ROD 450890-5 | C32: 450890-5 | D32: 5 | F32: - | H32: 107 | N32: ZP10 | Q32: =VLOOKUP(R32,'[1]MAKITA MASTERSHEET'!$E:$G,3,0) -> #N/A | S32: 1
A33: 40006150 | B33: MAKITA CONTROLLER 620040-8 RT0700C | C33: 620040-8 | D33: 7 | F33: - | H33: 278 | N33: GP28 | O33: AB96 | Q33: =VLOOKUP(R33,'[1]MAKITA MASTERSHEET'!$E:$G,3,0) -> #N/A
A34: 40007953 | B34: MAKITA CONTROLLER 631151-4 | C34: 631151-4 | D34: 9 | F34: - | H34: 2420 | O34: AB110
A35: 10019095 | B35: MAKITA DRILL BIT WOOD D-07222 20X335 | C35: D-07222 | D35: 3 | F35: - | H35: 159 | N35: 54
A36: 40005640 | B36: MAKITA FIELD 240V 633769-7 RT0700C | C36: 633769-7 | D36: 2 | F36: - | H36: 251 | N36: H22
A37: 40005943 | B37: MAKITA FRONT HANDLE 419409-9 | C37: 419409-9 | D37: 5 | F37: - | H37: 216 | O37: A10(BOX)
A38: 40007954 | B38: MAKITA GEAR COMPLETE 8-50 226134-3 | C38: 226134-3 | D38: 2 | F38: - | H38: 133 | N38: HC01
A39: 40006708 | B39: MAKITA GEAR HOUSING COMPLETE 140433-8 M | C39: 140433-8 | D39: 12 | F39: - | H39: 97 | N39: WA30
A40: 40006148 | B40: MAKITA GUID FANCE 318411-8 LS1016 | C40: 318411-8 | D40: 2 | F40: - | H40: 505 | O40: 39
...

Sheet Sheet1
B2: 10017912 | C2: MAKITA DC BAND SAW 18V 64MM DPB182Z
B3: 10017935 | C3: MAKITA MULTIFUNCTION POW.HEAD 18V DUX18Z
B4: 10017938 | C4: MAKITA DC POLISHER 40V BL 180MM PV001GZ
B5: 10017958 | C5: MAKITA DC COMBI HAMMER 40V HR007GZ
B6: 10017988 | C6: MAKITA CIRCULAR SAW HS7010 185MM
B7: 10018140 | C7: MAKITA LASER DISTANCE MEASURE LD080P 80M
B8: 10018434 | C8: MAKITA FINISHING SANDER110X110MM BO4510H
B9: 10018446 | C9: MAKITA DC HAMMER 18V BL 18MM DHR183RTWJ
B10: 10018482 | C10: MAKITA AC HAMMER DRILL 13MM M8103KX2B
B11: 10036226 | C11: MAKITA DC HEAT GUN 18V DHG180ZK
B12: 10044070 | C12: MAKITA DC TELESCOPIC POLE SAW UA002GM102

Sheet Sheet3
A2: SPECIAL OFFER 20% | B2: SPECIAL OFFER 20% | C2: SPECIAL OFFER 20% | D2: SPECIAL OFFER 10% | E2: SPECIAL OFFER 10% | F2: SPECIAL OFFER 10% | J2: Material | K2: Material Description | L2: Unrestr. | O2: M001 | Q2: 12580 | R2: 1 | S2: 11806 | T2: 2 | U2: 11830 | V2: 3 | W2: 13444 | X2: 4 | Y2: 11930 | Z2: 5 | AA2: 13096 | AB2: 6 | AC2: 11830 | AD2: 7 | AE2: 12770 | AF2: 8 | AG2: 11562 | AH2: 9 | AI2: 11565 | AJ2: 10 | AK2: 12484 | AL2: 11 | AM2: 11830 | AN2: 12 | AO2: 12792 | AP2: 13 | AR2: 14
A3: SPECIAL OFFER 30% | B3: SPECIAL OFFER 30% | C3: SPECIAL OFFER 30% | D3: SPECIAL OFFER 10% | E3: SPECIAL OFFER 10% | F3: SPECIAL OFFER 10% | J3: 10013659 | K3: MAKITA DRILL DP4700 (13MM) 1/2" | L3: 29 | O3: M001 | Q3: 13493 | R3: 1 | S3: 13576 | T3: 2 | U3: 12912 | V3: 3 | W3: 13060 | X3: 4 | Y3: 11996 | Z3: 5 | AA3: 11581 | AB3: 6 | AC3: 11881 | AD3: 7 | AE3: 13500 | AF3: 8 | AG3: 13505 | AH3: 9 | AI3: HR2470 | AJ3: 10 | AK3: 13505 | AL3: 11 | AN3: 12 | AO3: 13101 | AP3: 13 | AR3: 14
A4: SPECIAL OFFER 40% | B4: SPECIAL OFFER 40% | C4: SPECIAL OFFER 40% | D4: SPECIAL OFFER 10% | E4: SPECIAL OFFER 10% | F4: SPECIAL OFFER 10% | J4: 10013665 | K4: MAKITA C-LESS IMPACTDRVR TD090DWE 10.8V | L4: 5 | O4: M001 | Q4: 13584 | R4: 1 | S4: 13127 | T4: 2 | U4: 11668 | V4: 3 | W4: 11806 | X4: 4 | Y4: 13364 | Z4: 5 | AA4: 11834 | AB4: 6 | AC4: 11404 | AD4: 7 | AE4: 13454 | AF4: 8 | AG4: 13563 | AH4: 9 | AI4: 12970 | AJ4: 10 | AK4: 13127 | AL4: 11 | AN4: 12 | AO4: 13127 | AP4: 13 | AR4: 14
A5: SPECIAL OFFER 50% | B5: SPECIAL OFFER 50% | C5: SPECIAL OFFER 50% | D5: SPECIAL OFFER 20% | E5: SPECIAL OFFER 20% | F5: SPECIAL OFFER 20% | J5: 10013671 | K5: MAKITA DRILL 6412 (10MM) 3/8" | L5: 11 | O5: M001 | Q5: 13570 | R5: 1 | S5: 13492 | T5: 2 | U5: 11806 | V5: 3 | W5: 13454 | X5: 4 | Y5: 13377 | Z5: 5 | AA5: 11981 | AB5: 6 | AC5: 12049 | AD5: 7 | AE5: 11505 | AF5: 8 | AG5: 13508 | AH5: 9 | AI5: 12770 | AJ5: 10 | AL5: 11 | AN5: 12 | AP5: 13 | AR5: 14
A6: SPECIAL OFFER 50% | B6: SPECIAL OFFER 50% | C6: SPECIAL OFFER 50% | D6: SPECIAL OFFER 20% | E6: SPECIAL OFFER 20% | F6: SPECIAL OFFER 20% | J6: 10013672 | K6: MAKITA HAMMER-DRILL HP2050 (20MM) 3/4" | L6: 8 | O6: M001 | Q6: 13518 | R6: 1 | S6: 11386 | T6: 2 | U6: 11592 | V6: 3 | X6: 4 | Y6: 13465 | Z6: 5 | AA6: 11458 | AB6: 6 | AC6: 11177 | AD6: 7 | AF6: 8 | AG6: 11545 | AH6: 9 | AI6: 13218 | AJ6: 10 | AL6: 11 | AN6: 12 | AP6: 13 | AR6: 14
A7: SPECIAL OFFER 50% | B7: SPECIAL OFFER 50% | C7: SPECIAL OFFER 50% | D7: SPECIAL OFFER 20% | E7: SPECIAL OFFER 20% | F7: SPECIAL OFFER 20% | J7: 10013673 | K7: MAKITA HAMMER-DRILL HP2070 (20MM) 3/4" | L7: 2 | O7: M001 | R7: 1 | S7: 10160 | T7: 2 | U7: 11734 | V7: 3 | X7: 4 | Y7: 12422 | Z7: 5 | AA7: 12113 | AB7: 6 | AC7: 13428 | AD7: 7 | AF7: 8 | AG7: 13447 | AH7: 9 | AJ7: 10 | AL7: 11 | AN7: 12 | AP7: 13 | AR7: 14
A8: SPECIAL OFFER 50% | B8: SPECIAL OFFER 50% | C8: SPECIAL OFFER 50% | D8: SPECIAL OFFER 20% | E8: SPECIAL OFFER 20% | F8: SPECIAL OFFER 20% | J8: 10013683 | K8: MAKITA DEMOLITION HAMMER HM1306 (30MM) | L8: 2 | O8: M001 | R8: 1 | T8: 2 | U8: 12413 | V8: 3 | X8: 4 | Z8: 5 | AA8: 12703 | AB8: 6 | AC8: 13204 | AD8: 7 | AF8: 8 | AH8: 9 | AJ8: 10 | AL8: 11 | AN8: 12 | AP8: 13 | AR8: 14
A9: SPECIAL OFFER 50% | B9: SPECIAL OFFER 50% | C9: SPECIAL OFFER 50% | D9: SPECIAL OFFER 20% | E9: SPECIAL OFFER 20% | F9: SPECIAL OFFER 20% | J9: 10013684 | K9: MAKITA ROTARY HAMMER HR2810(3MODE) 28MM | L9: 10 | O9: M001 | R9: 1 | T9: 2 | U9: 11592 | V9: 3 | X9: 4 | Z9: 5 | AA9: 11386 | AB9: 6 | AD9: 7 | AF9: 8 | AH9: 9 | AJ9: 10 | AL9: 11 | AN9: 12 | AR9: 14
A10: SPECIAL OFFER 50% | B10: SPECIAL OFFER 50% | C10: SPECIAL OFFER 50% | D10: SPECIAL OFFER 30% | E10: SPECIAL OFFER 30% | F10: SPECIAL OFFER 30% | J10: 10013692 | K10: MAKITA IMPACT DRIVER TD0101F | L10: 41 | O10: M001 | R10: 1 | T10: 2 | U10: 12242 | V10: 3 | X10: 4 | Z10: 5 | AA10: 11816 | AB10: 6 | AD10: 7 | AF10: 8 | AH10: 9 | AJ10: 10 | AL10: 11 | AN10: 12 | AR10: 14
A11: SPECIAL OFFER 50% | B11: SPECIAL OFFER 50% | C11: SPECIAL OFFER 50% | D11: SPECIAL OFFER 30% | E11: SPECIAL OFFER 30% | F11: SPECIAL OFFER 30% | J11: 10013697 | K11: MAKITA POWER PLANER 1805N (6-1/8") 155MM | L11: 2 | O11: M001 | R11: 1 | T11: 2 | U11: 13488 | V11: 3 | X11: 4 | Z11: 5 | AA11: 11669 | AB11: 6 | AD11: 7 | AF11: 8 | AH11: 9 | AJ11: 10 | AL11: 11 | AN11: 12 | AR11: 14
A12: SPECIAL OFFER 50% | B12: SPECIAL OFFER 50% | C12: SPECIAL OFFER 50% | D12: SPECIAL OFFER 30% | E12: SPECIAL OFFER 30% | F12: SPECIAL OFFER 30% | J12: 10013698 | K12: MAKITA POWER PLANER 1911B (4-3/8") 110MM | L12: 12 | O12: M001 | R12: 1 | T12: 2 | U12: 13567 | V12: 3 | X12: 4 | Z12: 5 | AA12: 12700 | AB12: 6 | AD12: 7 | AF12: 8 | AH12: 9 | AJ12: 10 | AL12: 11 | AN12: 12 | AR12: 14
A13: SPECIAL OFFER 50% | B13: SPECIAL OFFER 50% | C13: SPECIAL OFFER 50% | D13: SPECIAL OFFER 30% | E13: SPECIAL OFFER 30% | F13: SPECIAL OFFER 30% | J13: 10013704 | K13: MAKITA PLANER 2012NB (304MM) 12" | L13: 1 | O13: M001 | R13: 1 | T13: 2 | U13: 11692 | V13: 3 | X13: 4 | Z13: 5 | AA13: 13550 | AB13: 6 | AD13: 7 | AF13: 8 | AH13: 9 | AJ13: 10 | AL13: 11 | AN13: 12 | AR13: 14
A14: SPECIAL OFFER 50% | B14: SPECIAL OFFER 50% | C14: SPECIAL OFFER 50% | D14: SPECIAL OFFER 30% | E14: SPECIAL OFFER 30% | F14: SPECIAL OFFER 30% | J14: 10013710 | K14: MAKITA CIRCULAR SAW 5103N(335MM) 13-1/8" | L14: 3 | O14: M001 | R14: 1 | T14: 2 | V14: 3 | X14: 4 | Z14: 5 | AA14: 11990 | AB14: 6 | AD14: 7 | AF14: 8 | AH14: 9 | AJ14: 10 | AL14: 11 | AN14: 12 | AR14: 14
A15: SPECIAL OFFER 50% | B15: SPECIAL OFFER 50% | C15: SPECIAL OFFER 50% | D15: SPECIAL OFFER 40% | E15: SPECIAL OFFER 40% | F15: SPECIAL OFFER 40% | J15: 10013713 | K15: MAKITA CIRCULAR SAW N5900B (235MM)9-1/4" | L15: 7 | O15: M001 | R15: 1 | T15: 2 | V15: 3 | X15: 4 | Z15: 5 | AA15: 11883 | AB15: 6 | AD15: 7 | AF15: 8 | AH15: 9 | AJ15: 10 | AL15: 11 | AN15: 12 | AR15: 14
A16: SPECIAL OFFER 50% | B16: SPECIAL OFFER 50% | C16: SPECIAL OFFER 50% | D16: SPECIAL OFFER 40% | E16: SPECIAL OFFER 40% | F16: SPECIAL OFFER 40% | J16: 10013716 | K16: MAKITA CIRCULAR SAW 5806B (185MM) 7-1/4" | L16: 50 | O16: M001 | R16: 1 | T16: 2 | V16: 3 | X16: 4 | Z16: 5 | AB16: 6 | AD16: 7 | AF16: 8 | AH16: 9 | AJ16: 10 | AL16: 11 | AN16: 12 | AR16: 14
A17: SPECIAL OFFER 50% | B17: SPECIAL OFFER 50% | C17: SPECIAL OFFER 50% | D17: SPECIAL OFFER 50% | E17: SPECIAL OFFER 50% | F17: SPECIAL OFFER 50% | J17: 10013719 | K17: MAKITA CIRCULAR SAW 5008MG (210MM)8-1/4" | L17: 6 | O17: M001
A18: SPECIAL OFFER 50% | B18: SPECIAL OFFER 50% | C18: SPECIAL OFFER 50% | D18: SPECIAL OFFER 50% | E18: SPECIAL OFFER 50% | F18: SPECIAL OFFER 50% | J18: 10013721 | K18: MAKITA COMPOUND MITER SAW LS1040 10-1/4" | L18: 17 | O18: M001
A19: SPECIAL OFFER 50% | B19: SPECIAL OFFER 50% | C19: SPECIAL OFFER 50% | D19: SPECIAL OFFER 50% | E19: SPECIAL OFFER 50% | F19: SPECIAL OFFER 50% | J19: 10013727 | K19: MAKITA JIGSAW 4327M (HOLE TYPE) | L19: 1 | O19: M001
A20: SPECIAL OFFER 50% | B20: SPECIAL OFFER 50% | C20: SPECIAL OFFER 50% | D20: SPECIAL OFFER 50% | E20: SPECIAL OFFER 50% | F20: SPECIAL OFFER 50% | J20: 10017888 | K20: MAKITA HIGH PER ENGINE OIL 980008606 | L20: 248 | O20: M001
A21: SPECIAL OFFER 70% | B21: SPECIAL OFFER 70% | C21: SPECIAL OFFER 70% | D21: SPECIAL OFFER 50% | E21: SPECIAL OFFER 50% | F21: SPECIAL OFFER 50% | J21: 10017889 | K21: MAKITA SAW CHAIN 10" SPROCKET 191H08-4 | L21: 5 | O21: M001
J22: 10017891 | K22: MAKITA DC HEDGE TRIMMER 18V DUH506Z | L22: 2 | O22: M001
J23: 10017894 | K23: MAKITA HAMMER CASE COMPLETE 144787-5 | L23: 7 | O23: M001
J24: 10017895 | K24: MAKITA AC VACUUM CLEANER 20L VC2000L | L24: 2 | O24: M001
J25: 10017896 | K25: MAKITA DC CLEANER 18V DCL286FRTB | L25: 6 | O25: M001
J26: 10017897 | K26: MAKITA DC HAMMER DRIVER DRILL DHP484RFE | L26: 1 | O26: M001
J27: 10017898 | K27: MAKITA DC HAMMER DRIVER DRILL DHP487RFJ | L27: 3 | O27: M001
J28: 10017899 | K28: MAKITA DC HEDGE TRIMMER 18V DUH507Z | L28: 2 | O28: M001
J29: 10017904 | K29: MAKITA DC CLEANER 40V CL003GZ14 | L29: 2 | O29: M001
J30: 10017905 | K30: MAKITA DC METAL CUTTER 40V 7" CS002GZ | L30: 7 | O30: M001
J31: 10017906 | K31: MAKITA DC CUT-OUT TOOL 18V DCO181Z | L31: 6 | O31: M001
J32: 10017915 | K32: MAKITA DC HEDGE TRIMMER 18V DUH751Z | L32: 2 | O32: M001
J33: 10017924 | K33: MAKITA DC CIRCULAR SAW 40V 9" HS010GZ | L33: 2 | O33: M001
... J38: 10017934 | K38: MAKITA DC RADIO WITH LANTERN 40V MR010G | L38: 6 | O38: M001
J39: 10017936 | K39: MAKITA DC MICROWAVE 40V 8L 500W MW001GZ | L39: 1
J40: 10017941 | K40: MAKITA DC CHAIN SAW 40V 12" UC003GZ01 | L40: 2
J41: 10017942 | K41: MAKITA DC ANGLEGRINDER 40V 150MM GA036GZ | L41: 1
J42: 10017943 | K42: MAKITA DC CHAIN SAW 40V 16" UC012GZ | L42: 2
J43: 10017944 | K43: MAKITA DC ANGLEGRINDER 40V 180MM GA037GZ | L43: 5
J44: 10017945 | K44: MAKITA DC CHAIN SAW 40V 12" UC014GZ | L44: 1
J45: 10017947 | K45: MAKITA DC CHAIN SAW 12V BL 100MM UC100DZ | L45: 2
...
